Workbook

Sheet 全日本品牌牛
A1: 編號 | B1: 地區 | C1: 都道府縣 | D1: 品牌名（日文） | E1: 品種 | F1: 已吃（填 ✓） | G1: 我吃過的名稱 | H1: 備註
A2: 1 | B2: 北海道 | C2: 北海道 | D2: 白老牛 | E2: 黑毛和種 | F2: ✓ | G2: 白老牛
A3: 2 | B3: 北海道 | C3: 北海道 | D3: 十勝和牛 | E3: 和牛 | F3: ✓ | G3: 十勝牛 | H3: 你記的「十勝牛」，對應最接近的十勝和牛
A4: 3 | B4: 北海道 | C4: 北海道 | D4: 十勝ナイタイ和牛 | E4: 和牛
A5: 4 | B5: 北海道 | C5: 北海道 | D5: 十勝ワインビーフ | E5: 黑毛和種 | H5: 池田町
A6: 5 | B6: 北海道 | C6: 北海道 | D6: 十勝若牛 | E6: 乳用種 | F6: ✓ | G6: 十勝若牛 | H6: 清水町，乳用種短期肥育
A7: 6 | B7: 北海道 | C7: 北海道 | D7: 雪美和牛・ゆたか | E7: 黑毛和種 | F7: ✓ | G7: 雪美和牛 | H7: 帶廣市トヨニシファーム，2024 年推出
A8: 7 | B8: 北海道 | C8: 北海道 | D8: 豊西牛 | E8: 乳用種 | H8: 帶廣市トヨニシファーム
A9: 8 | B9: 北海道 | C9: 北海道 | D9: びえい和牛 | E9: 黑毛和種 | F9: ✓ | G9: 美瑛牛 | H9: 美瑛町 Farms 千代田
A10: 9 | B10: 北海道 | C10: 北海道 | D10: ふらの和牛 | E10: 和牛
A11: 10 | B11: 北海道 | C11: 北海道 | D11: ふらの大地和牛 | E11: 和牛
A12: 11 | B12: 北海道 | C12: 北海道 | D12: かみふらの和牛 | E12: 和牛
A13: 12 | B13: 北海道 | C13: 北海道 | D13: 富良野牛（你吃過的名稱） | E13: 未標示 | F13: ✓ | G13: 富良野牛 | H13: 可能是ふらの和牛或ふらの大地和牛
A14: 13 | B14: 北海道 | C14: 北海道 | D14: サロマ和牛 | E14: 和牛 | F14: ✓ | G14: 佐呂間和牛 | H14: 佐呂間町
A15: 14 | B15: 北海道 | C15: 北海道 | D15: はやきた和牛 | E15: 和牛
A16: 15 | B16: 北海道 | C16: 北海道 | D16: 知床牛 | E16: 和牛
A17: 16 | B17: 北海道 | C17: 北海道 | D17: 北勝牛 | E17: 和牛
A18: 17 | B18: 北海道 | C18: 北海道 | D18: みついし牛 | E18: 和牛
A19: 18 | B19: 北海道 | C19: 北海道 | D19: 北海道和牛 | E19: 和牛
A20: 19 | B20: 北海道 | C20: 北海道 | D20: 北見和牛 | E20: 和牛
A21: 20 | B21: 北海道 | C21: 北海道 | D21: びらとり和牛 | E21: 和牛
A22: 21 | B22: 北海道 | C22: 北海道 | D22: 生田原高原和牛 | E22: 和牛
A23: 22 | B23: 北海道 | C23: 北海道 | D23: 音更町すずらん和牛 | E23: 和牛
A24: 23 | B24: 北海道 | C24: 北海道 | D24: 北海道オホーツクあばしり和牛 | E24: 和牛
A25: 24 | B25: 北海道 | C25: 北海道 | D25: ところ育ちオホーツク和牛 | E25: 和牛
A26: 25 | B26: 北海道 | C26: 北海道 | D26: とうや湖和牛 | E26: 和牛
... A36: 35 | B36: 北海道 | C36: 北海道 | D36: 別海牛 | E36: 其他／混合
A37: 36 | B37: 北海道 | C37: 北海道 | D37: しほろ牛 | E37: 乳用種 | H37: 士幌町
A38: 37 | B38: 東北 | C38: 青森 | D38: あおもり倉石牛 | E38: 未標示
A39: 38 | B39: 東北 | C39: 青森 | D39: あおもり十和田湖和牛 | E39: 和牛
A40: 39 | B40: 東北 | C40: 青森 | D40: 三戸・田子牛 | E40: 未標示
A41: 40 | B41: 東北 | C41: 青森 | D41: 東通牛 | E41: 未標示
A42: 41 | B42: 東北 | C42: 青森 | D42: 並木和牛 | E42: 和牛 | F42: ✓ | G42: 並木和牛 | H42: 八甲田山地區（依你提供）
A43: 42 | B43: 東北 | C43: 岩手 | D43: 前沢牛 | E43: 黑毛和種
A44: 43 | B44: 東北 | C44: 岩手 | D44: いわて牛 | E44: 未標示
A45: 44 | B45: 東北 | C45: 岩手 | D45: いわて奥州牛 | E45: 未標示
A46: 45 | B46: 東北 | C46: 岩手 | D46: いわて門崎丑 | E46: 黑毛和種 | F46: ✓ | G46: 門崎丑牛 | H46: 一關市門崎
A47: 46 | B47: 東北 | C47: 岩手 | D47: いわて短角牛 | E47: 日本短角種
A48: 47 | B48: 東北 | C48: 岩手 | D48: 江刺牛 | E48: 未標示
A49: 48 | B49: 東北 | C49: 岩手 | D49: 岩手しわ牛 | E49: 未標示
...

Sheet 各縣統計
A1: 地區 | B1: 都道府縣 | C1: 收錄品牌數 | D1: 已吃數 | E1: 已吃比例
A2: 北海道 | B2: 北海道 | C2: =COUNTIF(全日本品牌牛!$C$2:$C$227,B2) -> 36 | D2: =COUNTIFS(全日本品牌牛!$C$2:$C$227,B2,全日本品牌牛!$F$2:$F$227,"✓") -> 7 | E2: =IF(C2=0,0,D2/C2) -> 0.19444444
A3: 東北 | B3: 青森 | C3: =COUNTIF(全日本品牌牛!$C$2:$C$227,B3) -> 5 | D3: =COUNTIFS(全日本品牌牛!$C$2:$C$227,B3,全日本品牌牛!$F$2:$F$227,"✓") -> 1 | E3: =IF(C3=0,0,D3/C3) -> 0.2
A4: 東北 | B4: 岩手 | C4: =COUNTIF(全日本品牌牛!$C$2:$C$227,B4) -> 10 | D4: =COUNTIFS(全日本品牌牛!$C$2:$C$227,B4,全日本品牌牛!$F$2:$F$227,"✓") -> 1 | E4: =IF(C4=0,0,D4/C4) -> 0.1
A5: 東北 | B5: 宮城 | C5: =COUNTIF(全日本品牌牛!$C$2:$C$227,B5) -> 6 | D5: =COUNTIFS(全日本品牌牛!$C$2:$C$227,B5,全日本品牌牛!$F$2:$F$227,"✓") -> 1 | E5: =IF(C5=0,0,D5/C5) -> 0.16666667
A6: 東北 | B6: 秋田 | C6: =COUNTIF(全日本品牌牛!$C$2:$C$227,B6) -> 5 | D6: =COUNTIFS(全日本品牌牛!$C$2:$C$227,B6,全日本品牌牛!$F$2:$F$227,"✓") -> 0 | E6: =IF(C6=0,0,D6/C6) -> 0
A7: 東北 | B7: 山形 | C7: =COUNTIF(全日本品牌牛!$C$2:$C$227,B7) -> 4 | D7: =COUNTIFS(全日本品牌牛!$C$2:$C$227,B7,全日本品牌牛!$F$2:$F$227,"✓") -> 3 | E7: =IF(C7=0,0,D7/C7) -> 0.75
A8: 東北 | B8: 福島 | C8: =COUNTIF(全日本品牌牛!$C$2:$C$227,B8) -> 3 | D8: =COUNTIFS(全日本品牌牛!$C$2:$C$227,B8,全日本品牌牛!$F$2:$F$227,"✓") -> 0 | E8: =IF(C8=0,0,D8/C8) -> 0
A9: 關東 | B9: 茨城 | C9: =COUNTIF(全日本品牌牛!$C$2:$C$227,B9) -> 6 | D9: =COUNTIFS(全日本品牌牛!$C$2:$C$227,B9,全日本品牌牛!$F$2:$F$227,"✓") -> 1 | E9: =IF(C9=0,0,D9/C9) -> 0.16666667
A10: 關東 | B10: 栃木 | C10: =COUNTIF(全日本品牌牛!$C$2:$C$227,B10) -> 8 | D10: =COUNTIFS(全日本品牌牛!$C$2:$C$227,B10,全日本品牌牛!$F$2:$F$227,"✓") -> 0 | E10: =IF(C10=0,0,D10/C10) -> 0
A11: 關東 | B11: 群馬 | C11: =COUNTIF(全日本品牌牛!$C$2:$C$227,B11) -> 4 | D11: =COUNTIFS(全日本品牌牛!$C$2:$C$227,B11,全日本品牌牛!$F$2:$F$227,"✓") -> 1 | E11: =IF(C11=0,0,D11/C11) -> 0.25
A12: 關東 | B12: 埼玉 | C12: =COUNTIF(全日本品牌牛!$C$2:$C$227,B12) -> 3 | D12: =COUNTIFS(全日本品牌牛!$C$2:$C$227,B12,全日本品牌牛!$F$2:$F$227,"✓") -> 0 | E12: =IF(C12=0,0,D12/C12) -> 0
A13: 關東 | B13: 千葉 | C13: =COUNTIF(全日本品牌牛!$C$2:$C$227,B13) -> 6 | D13: =COUNTIFS(全日本品牌牛!$C$2:$C$227,B13,全日本品牌牛!$F$2:$F$227,"✓") -> 0 | E13: =IF(C13=0,0,D13/C13) -> 0
... A48: 九州・沖繩 | B48: 沖繩 | C48: =COUNTIF(全日本品牌牛!$C$2:$C$227,B48) -> 3 | D48: =COUNTIFS(全日本品牌牛!$C$2:$C$227,B48,全日本品牌牛!$F$2:$F$227,"✓") -> 1 | E48: =IF(C48=0,0,D48/C48) -> 0.33333333
A49: 跨縣品牌 | B49: — | C49: =COUNTIF(全日本品牌牛!$B$2:$B$227,"跨縣") -> 2 | D49: =COUNTIFS(全日本品牌牛!$B$2:$B$227,"跨縣",全日本品牌牛!$F$2:$F$227,"✓") -> 1 | E49: =IF(C49=0,0,D49/C49) -> 0.5
A50: 合計 | C50: =SUM(C2:C49) -> 226 | D50: =SUM(D2:D49) -> 34 | E50: =IF(C50=0,0,D50/C50) -> 0.15044248

Sheet 說明
A1: 怎麼用
A2: 已吃欄 | B2: 在「全日本品牌牛」的 F 欄填 ✓，「各縣統計」會自動更新已吃數與比例。黃底格是還沒吃過、可以填的格子。
A3: 我吃過的名稱 | B3: 你原本記的品牌名；和日文官方名稱不同時，備註欄有說明。
A4: 品種 | B4: 只在來源寫明，或品牌本身定義品種時標示；其餘為「未標示」。
A6: 資料來源
A7: 1 | B7: 維基百科「日本のブランド牛一覧」 https://ja.wikipedia.org/wiki/日本のブランド牛一覧
A8: 2 | B8: 日本全国のブランド牛肉・銘柄牛一覧 https://brand-meat.com/brand-beef-index/
A9: 3 | B9: 和牛／銘柄牛 都道府県別一覧 https://www.penguin-toyu.net/otoriyose/wagyu.html
A10: 4 | B10: 你吃過但不在以上名單的品牌，依品牌官網與縣政資料補上（例如雪美和牛、びえい和牛、銀山和牛、九州王）
A12: 注意 | B12: 日本實際的品牌牛超過本表數量，這份是 2026 年 10 月整理的參考清單。
